/gpfs/soma_fs/scratch/meulemeester/anaconda_isf3/lib/python3.8/site-packages/distributed/cli/dask_scheduler.py:146: UserWarning: The --bokeh-port flag has been renamed to --dashboard-address. Consider adding ``--dashboard-address :38787`` 
  warnings.warn(
distributed.scheduler - INFO - -----------------------------------------------
distributed.http.proxy - INFO - To route to workers diagnostics web server please install jupyter-server-proxy: python -m pip install jupyter-server-proxy
distributed.scheduler - INFO - -----------------------------------------------
distributed.scheduler - INFO - Clear task state
distributed.scheduler - INFO -   Scheduler at:    tcp://10.30.0.61:38786
distributed.scheduler - INFO -   dashboard at:                    :38787
distributed.scheduler - INFO - End scheduler at 'tcp://10.30.0.61:38786'
Traceback (most recent call last):
  File "/gpfs/soma_fs/scratch/meulemeester/anaconda_isf3/bin/dask-scheduler", line 11, in <module>
    sys.exit(go())
  File "/gpfs/soma_fs/scratch/meulemeester/anaconda_isf3/lib/python3.8/site-packages/distributed/cli/dask_scheduler.py", line 226, in go
    main()
  File "/gpfs/soma_fs/scratch/meulemeester/anaconda_isf3/lib/python3.8/site-packages/click/core.py", line 829, in __call__
    return self.main(*args, **kwargs)
  File "/gpfs/soma_fs/scratch/meulemeester/anaconda_isf3/lib/python3.8/site-packages/click/core.py", line 782, in main
    rv = self.invoke(ctx)
  File "/gpfs/soma_fs/scratch/meulemeester/anaconda_isf3/lib/python3.8/site-packages/click/core.py", line 1066, in invoke
    return ctx.invoke(self.callback, **ctx.params)
  File "/gpfs/soma_fs/scratch/meulemeester/anaconda_isf3/lib/python3.8/site-packages/click/core.py", line 610, in invoke
    return callback(*args, **kwargs)
  File "/gpfs/soma_fs/scratch/meulemeester/anaconda_isf3/lib/python3.8/site-packages/distributed/cli/dask_scheduler.py", line 217, in main
    loop.run_sync(run)
  File "/gpfs/soma_fs/scratch/meulemeester/anaconda_isf3/lib/python3.8/site-packages/tornado/ioloop.py", line 526, in run_sync
    raise TimeoutError("Operation timed out after %s seconds" % timeout)
asyncio.exceptions.TimeoutError: Operation timed out after None seconds
